<!-- ======================================================
# Copyright 2017 The dm_control Authors.
#
# Licensed under the Apache License, Version 2.0 (the "License");
# you may not use this file except in compliance with the License.
# You may obtain a copy of the License at
#
#    http://www.apache.org/licenses/LICENSE-2.0
#
# Unless required by applicable law or agreed to in writing, software
# distributed under the License is distributed on an "AS IS" BASIS,
# WITHOUT WARRANTIES OR CONDITIONS OF ANY KIND, either express or  implied.
# See the License for the specific language governing permissions and
# limitations under the License.
====================================================== -->

<mujoco model="quadruped">
  <compiler angle="degree" coordinate="local" inertiafromgeom="true"/>
  <option integrator="RK4" timestep="0.0025"/>
  <custom>
    <numeric data="0.0 0.0 0.0 1.0 0.0 0.0 0.0 0.0 0.0 0.0 0.0 0.0 0.0 0.0 0.0 0.0 0.0 0.0 0.0 0.0 0.0 0.0 0.0 0.0 0.0 0.0 0.0 0.0 0.0 0.0" name="init_qpos"/>
  </custom>
  <default>
    <joint armature="0.01" damping=".1" limited="true" solimplimit="0 .99 .01"/>
    <geom conaffinity="0" condim="3" friction=".7 .1 .1" margin="0.01" rgba="0.8 0.6 0.4 1"/>
    <motor ctrlrange="-1 1" ctrllimited="true"/>
    <site size="0.01"/>
    <default class="quadruped">
      <geom material="geom" type="capsule"/>
      <joint axis="0 -1 0"/>
    </default>
  </default>
  <asset>
    <texture builtin="gradient" height="100" rgb1="1 1 1" rgb2="0 0 0" type="skybox" width="100"/>
    <texture builtin="flat" height="1278" mark="cross" markrgb="1 1 1" name="texgeom" random="0.01" rgb1="0.8 0.6 0.4" rgb2="0.8 0.6 0.4" type="cube" width="127"/>
    <texture builtin="checker" height="100" name="texplane" rgb1="0 0 0" rgb2="0.8 0.8 0.8" type="2d" width="100"/>
    <material name="MatPlane" reflectance="0.5" shininess="1" specular="1" texrepeat="60 60" texture="texplane"/>
    <material name="geom" texture="texgeom" texuniform="true"/>
  </asset>
  <worldbody>
    <light cutoff="100" diffuse="1 1 1" dir="-0 0 -1.3" directional="true" exponent="1" pos="0 0 1.3" specular=".1 .1 .1"/>
    <geom conaffinity="1" condim="3" material="MatPlane" name="floor" pos="248 0 0" rgba="0.8 0.9 0.8 1" size="250 .8 .2" type="plane" zaxis="0 0 1"/>
    <body name="torso" pos="0 0 0.57" childclass="quadruped">
      <camera name="side" pos="0 -2 .7" euler="60 0 0" mode="trackcom"/>
      <camera name="back" pos="-2 0 .5" xyaxes="0 -1 0 1 0 3" mode="trackcom"/>
      <joint name="rootz" axis="0 0 1" type="slide" limited="false" armature="0" damping="0"/>
      <joint name="rootx" axis="1 0 0" type="slide" limited="false" armature="0" damping="0"/>
      <joint name="rooty" axis="0 1 0" type="hinge" limited="false" armature="0" damping="0"/>
      <geom name="torso" size="0.3 0.27 0.2" type="ellipsoid"/>
      
      <!-- Front Left Leg -->
      <body name="hip_front_left" pos="0.2 0.2 0" euler="0 0 45">
        <joint name="yaw_front_left" axis="0 0 1" range="-50 50"/>
        <joint name="pitch_front_left" axis="0 1 0" range="-20 60"/>
        <geom name="thigh_front_left" fromto="0 0 0 0.3 0 0.11" size="0.08"/>
        <body name="knee_front_left" pos="0.3 0 0.11">
          <joint name="knee_front_left" axis="0 1 0" range="-60 50"/>
          <geom name="shin_front_left" fromto="0 0 0 0.25 0 -0.25" size="0.065"/>
          <body name="ankle_front_left" pos="0.25 0 -0.25">
            <joint name="ankle_front_left" axis="0 1 0" range="-45 55"/>
            <geom name="foot_front_left" fromto="0 0 0 0 0 -0.25" size="0.055"/>
            <body name="toe_front_left" pos="0 0 -0.3">
              <geom name="toe_front_left" size="0.08" type="sphere" friction="1.5"/>
            </body>
          </body>
        </body>
      </body>

      <!-- Front Right Leg -->
      <body name="hip_front_right" pos="0.2 -0.2 0" euler="0 0 -45">
        <joint name="yaw_front_right" axis="0 0 1" range="-50 50"/>
        <joint name="pitch_front_right" axis="0 1 0" range="-20 60"/>
        <geom name="thigh_front_right" fromto="0 0 0 0.3 0 0.11" size="0.08"/>
        <body name="knee_front_right" pos="0.3 0 0.11">
          <joint name="knee_front_right" axis="0 1 0" range="-60 50"/>
          <geom name="shin_front_right" fromto="0 0 0 0.25 0 -0.25" size="0.065"/>
          <body name="ankle_front_right" pos="0.25 0 -0.25">
            <joint name="ankle_front_right" axis="0 1 0" range="-45 55"/>
            <geom name="foot_front_right" fromto="0 0 0 0 0 -0.25" size="0.055"/>
            <body name="toe_front_right" pos="0 0 -0.3">
              <geom name="toe_front_right" size="0.08" type="sphere" friction="1.5"/>
            </body>
          </body>
        </body>
      </body>

      <!-- Back Right Leg -->
      <body name="hip_back_right" pos="-0.2 -0.2 0" euler="0 0 -135">
        <joint name="yaw_back_right" axis="0 0 1" range="-50 50"/>
        <joint name="pitch_back_right" axis="0 1 0" range="-20 60"/>
        <geom name="thigh_back_right" fromto="0 0 0 0.3 0 0.11" size="0.08"/>
        <body name="knee_back_right" pos="0.3 0 0.11">
          <joint name="knee_back_right" axis="0 1 0" range="-60 50"/>
          <geom name="shin_back_right" fromto="0 0 0 0.25 0 -0.25" size="0.065"/>
          <body name="ankle_back_right" pos="0.25 0 -0.25">
            <joint name="ankle_back_right" axis="0 1 0" range="-45 55"/>
            <geom name="foot_back_right" fromto="0 0 0 0 0 -0.25" size="0.055"/>
            <body name="toe_back_right" pos="0 0 -0.3">
              <geom name="toe_back_right" size="0.08" type="sphere" friction="1.5"/>
            </body>
          </body>
        </body>
      </body>

      <!-- Back Left Leg -->
      <body name="hip_back_left" pos="-0.2 0.2 0" euler="0 0 135">
        <joint name="yaw_back_left" axis="0 0 1" range="-50 50"/>
        <joint name="pitch_back_left" axis="0 1 0" range="-20 60"/>
        <geom name="thigh_back_left" fromto="0 0 0 0.3 0 0.11" size="0.08"/>
        <body name="knee_back_left" pos="0.3 0 0.11">
          <joint name="knee_back_left" axis="0 1 0" range="-60 50"/>
          <geom name="shin_back_left" fromto="0 0 0 0.25 0 -0.25" size="0.065"/>
          <body name="ankle_back_left" pos="0.25 0 -0.25">
            <joint name="ankle_back_left" axis="0 1 0" range="-45 55"/>
            <geom name="foot_back_left" fromto="0 0 0 0 0 -0.25" size="0.055"/>
            <body name="toe_back_left" pos="0 0 -0.3">
              <geom name="toe_back_left" size="0.08" type="sphere" friction="1.5"/>
            </body>
          </body>
        </body>
      </body>
    </body>
  </worldbody>
  <sensor>
    <subtreelinvel name="torso_subtreelinvel" body="torso"/>
  </sensor>
  <actuator>
    <!-- Front Left Leg -->
    <motor name="yaw_front_left" joint="yaw_front_left" gear="100"/>
    <motor name="pitch_front_left" joint="pitch_front_left" gear="100"/>
    <motor name="knee_front_left" joint="knee_front_left" gear="50"/>
    <motor name="ankle_front_left" joint="ankle_front_left" gear="20"/>
    
    <!-- Front Right Leg -->
    <motor name="yaw_front_right" joint="yaw_front_right" gear="100"/>
    <motor name="pitch_front_right" joint="pitch_front_right" gear="100"/>
    <motor name="knee_front_right" joint="knee_front_right" gear="50"/>
    <motor name="ankle_front_right" joint="ankle_front_right" gear="20"/>
    
    <!-- Back Right Leg -->
    <motor name="yaw_back_right" joint="yaw_back_right" gear="100"/>
    <motor name="pitch_back_right" joint="pitch_back_right" gear="100"/>
    <motor name="knee_back_right" joint="knee_back_right" gear="50"/>
    <motor name="ankle_back_right" joint="ankle_back_right" gear="20"/>
    
    <!-- Back Left Leg -->
    <motor name="yaw_back_left" joint="yaw_back_left" gear="100"/>
    <motor name="pitch_back_left" joint="pitch_back_left" gear="100"/>
    <motor name="knee_back_left" joint="knee_back_left" gear="50"/>
    <motor name="ankle_back_left" joint="ankle_back_left" gear="20"/>
  </actuator>
</mujoco> 