<!-- ======================================================
# Copyright 2017 The dm_control Authors.
#
# Licensed under the Apache License, Version 2.0 (the "License");
# you may not use this file except in compliance with the License.
# You may obtain a copy of the License at
#
#    http://www.apache.org/licenses/LICENSE-2.0
#
# Unless required by applicable law or agreed to in writing, software
# distributed under the License is distributed on an "AS IS" BASIS,
# WITHOUT WARRANTIES OR CONDITIONS OF ANY KIND, either express or  implied.
# See the License for the specific language governing permissions and
# limitations under the License.
====================================================== -->

<mujoco model="planar walker">
  <compiler angle="degree" coordinate="local" inertiafromgeom="true"/>
  <option integrator="RK4" timestep="0.0025"/>
  <custom>
    <numeric data="0.0 0.0 1.3 1.0 0.0 0.0 0.0 0.0 0.0 0.0 0.0 0.0 0.0 0.0 0.0" name="init_qpos"/>
  </custom>
  <default>
    <joint armature="0.01" damping=".1" limited="true" solimplimit="0 .99 .01"/>
    <geom conaffinity="0" condim="3" friction=".7 .1 .1" margin="0.01" rgba="0.8 0.6 0.4 1"/>
    <motor ctrlrange="-1 1" ctrllimited="true"/>
    <site size="0.01"/>
    <default class="walker">
      <geom material="geom" type="capsule"/>
      <joint axis="0 -1 0"/>
    </default>
  </default>
  <asset>
    <texture builtin="gradient" height="100" rgb1="1 1 1" rgb2="0 0 0" type="skybox" width="100"/>
    <texture builtin="flat" height="1278" mark="cross" markrgb="1 1 1" name="texgeom" random="0.01" rgb1="0.8 0.6 0.4" rgb2="0.8 0.6 0.4" type="cube" width="127"/>
    <texture builtin="checker" height="100" name="texplane" rgb1="0 0 0" rgb2="0.8 0.8 0.8" type="2d" width="100"/>
    <material name="MatPlane" reflectance="0.5" shininess="1" specular="1" texrepeat="60 60" texture="texplane"/>
    <material name="geom" texture="texgeom" texuniform="true"/>
  </asset>
  <worldbody>
    <light cutoff="100" diffuse="1 1 1" dir="-0 0 -1.3" directional="true" exponent="1" pos="0 0 1.3" specular=".1 .1 .1"/>
    <geom conaffinity="1" condim="3" material="MatPlane" name="floor" pos="248 0 0" rgba="0.8 0.9 0.8 1" size="250 .8 .2" type="plane" zaxis="0 0 1"/>
    <body name="torso" pos="0 0 1.3" childclass="walker">
      <camera name="side" pos="0 -2 .7" euler="60 0 0" mode="trackcom"/>
      <camera name="back" pos="-2 0 .5" xyaxes="0 -1 0 1 0 3" mode="trackcom"/>
      <joint name="rootz" axis="0 0 1" type="slide" limited="false" armature="0" damping="0"/>
      <joint name="rootx" axis="1 0 0" type="slide" limited="false" armature="0" damping="0"/>
      <joint name="rooty" axis="0 1 0" type="hinge" limited="false" armature="0" damping="0"/>
      <geom name="torso" size="0.07 0.3"/>
      <body name="right_thigh" pos="0 -.05 -0.3">
        <joint name="right_hip" range="-20 100"/>
        <geom name="right_thigh" pos="0 0 -0.225" size="0.05 0.225"/>
        <body name="right_leg" pos="0 0 -0.7">
          <joint name="right_knee" pos="0 0 0.25" range="-150 0"/>
          <geom name="right_leg" size="0.04 0.25"/>
          <body name="right_foot" pos="0.06 0 -0.25">
            <joint name="right_ankle" pos="-0.06 0 0" range="-45 45"/>
            <geom name="right_foot" zaxis="1 0 0" size="0.05 0.1"/>
          </body>
        </body>
      </body>
      <body name="left_thigh" pos="0 .05 -0.3" >
        <joint name="left_hip" range="-20 100"/>
        <geom name="left_thigh" pos="0 0 -0.225" size="0.05 0.225"/>
        <body name="left_leg" pos="0 0 -0.7">
          <joint name="left_knee" pos="0 0 0.25" range="-150 0"/>
          <geom name="left_leg" size="0.04 0.25"/>
          <body name="left_foot" pos="0.06 0 -0.25">
            <joint name="left_ankle" pos="-0.06 0 0" range="-45 45"/>
            <geom name="left_foot" zaxis="1 0 0" size="0.05 0.1"/>
          </body>
        </body>
      </body>
    </body>
  </worldbody>
  <sensor>
    <subtreelinvel name="torso_subtreelinvel" body="torso"/>
  </sensor>
  <actuator>
    <motor name="right_hip" joint="right_hip" gear="100"/>
    <motor name="right_knee" joint="right_knee" gear="50"/>
    <motor name="right_ankle" joint="right_ankle" gear="20"/>
    <motor name="left_hip" joint="left_hip" gear="100"/>
    <motor name="left_knee" joint="left_knee" gear="50"/>
    <motor name="left_ankle" joint="left_ankle" gear="20"/>
  </actuator>
</mujoco> 